Exception on /prodi_piechart/5 [GET]
Traceback (most recent call last):
  File "D:\Program\Anaconda\envs\TA\lib\site-packages\flask\app.py", line 2447, in wsgi_app
    response = self.full_dispatch_request()
  File "D:\Program\Anaconda\envs\TA\lib\site-packages\flask\app.py", line 1952, in full_dispatch_request
    rv = self.handle_user_exception(e)
  File "D:\Program\Anaconda\envs\TA\lib\site-packages\flask\app.py", line 1821, in handle_user_exception
    reraise(exc_type, exc_value, tb)
  File "D:\Program\Anaconda\envs\TA\lib\site-packages\flask\_compat.py", line 39, in reraise
    raise value
  File "D:\Program\Anaconda\envs\TA\lib\site-packages\flask\app.py", line 1950, in full_dispatch_request
    rv = self.dispatch_request()
  File "D:\Program\Anaconda\envs\TA\lib\site-packages\flask\app.py", line 1936, in dispatch_request
    return self.view_functions[rule.endpoint](**req.view_args)
  File "D:/Proyek/TA/realtime/main.py", line 215, in prodi_piechart
    df = pd.read_excel(excel)
  File "D:\Program\Anaconda\envs\TA\lib\site-packages\pandas\util\_decorators.py", line 296, in wrapper
    return func(*args, **kwargs)
  File "D:\Program\Anaconda\envs\TA\lib\site-packages\pandas\io\excel\_base.py", line 304, in read_excel
    io = ExcelFile(io, engine=engine)
  File "D:\Program\Anaconda\envs\TA\lib\site-packages\pandas\io\excel\_base.py", line 867, in __init__
    self._reader = self._engines[engine](self._io)
  File "D:\Program\Anaconda\envs\TA\lib\site-packages\pandas\io\excel\_xlrd.py", line 22, in __init__
    super().__init__(filepath_or_buffer)
  File "D:\Program\Anaconda\envs\TA\lib\site-packages\pandas\io\excel\_base.py", line 353, in __init__
    self.book = self.load_workbook(filepath_or_buffer)
  File "D:\Program\Anaconda\envs\TA\lib\site-packages\pandas\io\excel\_xlrd.py", line 37, in load_workbook
    return open_workbook(filepath_or_buffer)
  File "D:\Program\Anaconda\envs\TA\lib\site-packages\xlrd\__init__.py", line 116, in open_workbook
    with open(filename, "rb") as f:
FileNotFoundError: [Errno 2] No such file or directory: '../public_html/cdc/excel/kuesioner/Tracer_Study_Lulusan_2018.xlsx'
Exception on /prodi_piechart/5 [GET]
Traceback (most recent call last):
  File "D:\Program\Anaconda\envs\TA\lib\site-packages\flask\app.py", line 2447, in wsgi_app
    response = self.full_dispatch_request()
  File "D:\Program\Anaconda\envs\TA\lib\site-packages\flask\app.py", line 1952, in full_dispatch_request
    rv = self.handle_user_exception(e)
  File "D:\Program\Anaconda\envs\TA\lib\site-packages\flask\app.py", line 1821, in handle_user_exception
    reraise(exc_type, exc_value, tb)
  File "D:\Program\Anaconda\envs\TA\lib\site-packages\flask\_compat.py", line 39, in reraise
    raise value
  File "D:\Program\Anaconda\envs\TA\lib\site-packages\flask\app.py", line 1950, in full_dispatch_request
    rv = self.dispatch_request()
  File "D:\Program\Anaconda\envs\TA\lib\site-packages\flask\app.py", line 1936, in dispatch_request
    return self.view_functions[rule.endpoint](**req.view_args)
  File "D:/Proyek/TA/realtime/main.py", line 215, in prodi_piechart
    df = pd.read_excel(excel)
  File "D:\Program\Anaconda\envs\TA\lib\site-packages\pandas\util\_decorators.py", line 296, in wrapper
    return func(*args, **kwargs)
  File "D:\Program\Anaconda\envs\TA\lib\site-packages\pandas\io\excel\_base.py", line 304, in read_excel
    io = ExcelFile(io, engine=engine)
  File "D:\Program\Anaconda\envs\TA\lib\site-packages\pandas\io\excel\_base.py", line 867, in __init__
    self._reader = self._engines[engine](self._io)
  File "D:\Program\Anaconda\envs\TA\lib\site-packages\pandas\io\excel\_xlrd.py", line 22, in __init__
    super().__init__(filepath_or_buffer)
  File "D:\Program\Anaconda\envs\TA\lib\site-packages\pandas\io\excel\_base.py", line 353, in __init__
    self.book = self.load_workbook(filepath_or_buffer)
  File "D:\Program\Anaconda\envs\TA\lib\site-packages\pandas\io\excel\_xlrd.py", line 37, in load_workbook
    return open_workbook(filepath_or_buffer)
  File "D:\Program\Anaconda\envs\TA\lib\site-packages\xlrd\__init__.py", line 116, in open_workbook
    with open(filename, "rb") as f:
FileNotFoundError: [Errno 2] No such file or directory: '../public_html/cdc/excel/kuesioner/Tracer_Study_Lulusan_2018.xlsx'
Exception on /prodi_piechart/5 [GET]
Traceback (most recent call last):
  File "D:\Program\Anaconda\envs\TA\lib\site-packages\flask\app.py", line 2447, in wsgi_app
    response = self.full_dispatch_request()
  File "D:\Program\Anaconda\envs\TA\lib\site-packages\flask\app.py", line 1952, in full_dispatch_request
    rv = self.handle_user_exception(e)
  File "D:\Program\Anaconda\envs\TA\lib\site-packages\flask\app.py", line 1821, in handle_user_exception
    reraise(exc_type, exc_value, tb)
  File "D:\Program\Anaconda\envs\TA\lib\site-packages\flask\_compat.py", line 39, in reraise
    raise value
  File "D:\Program\Anaconda\envs\TA\lib\site-packages\flask\app.py", line 1950, in full_dispatch_request
    rv = self.dispatch_request()
  File "D:\Program\Anaconda\envs\TA\lib\site-packages\flask\app.py", line 1936, in dispatch_request
    return self.view_functions[rule.endpoint](**req.view_args)
  File "D:/Proyek/TA/realtime/main.py", line 215, in prodi_piechart
    df = pd.read_excel(excel)
  File "D:\Program\Anaconda\envs\TA\lib\site-packages\pandas\util\_decorators.py", line 296, in wrapper
    return func(*args, **kwargs)
  File "D:\Program\Anaconda\envs\TA\lib\site-packages\pandas\io\excel\_base.py", line 304, in read_excel
    io = ExcelFile(io, engine=engine)
  File "D:\Program\Anaconda\envs\TA\lib\site-packages\pandas\io\excel\_base.py", line 867, in __init__
    self._reader = self._engines[engine](self._io)
  File "D:\Program\Anaconda\envs\TA\lib\site-packages\pandas\io\excel\_xlrd.py", line 22, in __init__
    super().__init__(filepath_or_buffer)
  File "D:\Program\Anaconda\envs\TA\lib\site-packages\pandas\io\excel\_base.py", line 353, in __init__
    self.book = self.load_workbook(filepath_or_buffer)
  File "D:\Program\Anaconda\envs\TA\lib\site-packages\pandas\io\excel\_xlrd.py", line 37, in load_workbook
    return open_workbook(filepath_or_buffer)
  File "D:\Program\Anaconda\envs\TA\lib\site-packages\xlrd\__init__.py", line 116, in open_workbook
    with open(filename, "rb") as f:
FileNotFoundError: [Errno 2] No such file or directory: '../public_html/cdc/excel/kuesioner/Tracer_Study_Lulusan_2018.xlsx'
Exception on /piechart/3 [GET]
Traceback (most recent call last):
  File "/home/tracerstudy/virtualenv/realtime/3.6/lib/python3.6/site-packages/flask/app.py", line 2447, in wsgi_app
    response = self.full_dispatch_request()
  File "/home/tracerstudy/virtualenv/realtime/3.6/lib/python3.6/site-packages/flask/app.py", line 1952, in full_dispatch_request
    rv = self.handle_user_exception(e)
  File "/home/tracerstudy/virtualenv/realtime/3.6/lib/python3.6/site-packages/flask/app.py", line 1821, in handle_user_exception
    reraise(exc_type, exc_value, tb)
  File "/home/tracerstudy/virtualenv/realtime/3.6/lib/python3.6/site-packages/flask/_compat.py", line 39, in reraise
    raise value
  File "/home/tracerstudy/virtualenv/realtime/3.6/lib/python3.6/site-packages/flask/app.py", line 1950, in full_dispatch_request
    rv = self.dispatch_request()
  File "/home/tracerstudy/virtualenv/realtime/3.6/lib/python3.6/site-packages/flask/app.py", line 1936, in dispatch_request
    return self.view_functions[rule.endpoint](**req.view_args)
  File "/home/tracerstudy/realtime/main.py", line 66, in piechart
    df = pd.read_excel(excel)
  File "/home/tracerstudy/virtualenv/realtime/3.6/lib/python3.6/site-packages/pandas/util/_decorators.py", line 296, in wrapper
    return func(*args, **kwargs)
  File "/home/tracerstudy/virtualenv/realtime/3.6/lib/python3.6/site-packages/pandas/io/excel/_base.py", line 304, in read_excel
    io = ExcelFile(io, engine=engine)
  File "/home/tracerstudy/virtualenv/realtime/3.6/lib/python3.6/site-packages/pandas/io/excel/_base.py", line 867, in __init__
    self._reader = self._engines[engine](self._io)
  File "/home/tracerstudy/virtualenv/realtime/3.6/lib/python3.6/site-packages/pandas/io/excel/_xlrd.py", line 21, in __init__
    import_optional_dependency("xlrd", extra=err_msg)
  File "/home/tracerstudy/virtualenv/realtime/3.6/lib/python3.6/site-packages/pandas/compat/_optional.py", line 110, in import_optional_dependency
    raise ImportError(msg) from None
ImportError: Missing optional dependency 'xlrd'. Install xlrd >= 1.0.0 for Excel support Use pip or conda to install xlrd.
Exception on /piechart_non/3 [GET]
Traceback (most recent call last):
  File "/home/tracerstudy/virtualenv/realtime/3.6/lib/python3.6/site-packages/flask/app.py", line 2447, in wsgi_app
    response = self.full_dispatch_request()
  File "/home/tracerstudy/virtualenv/realtime/3.6/lib/python3.6/site-packages/flask/app.py", line 1952, in full_dispatch_request
    rv = self.handle_user_exception(e)
  File "/home/tracerstudy/virtualenv/realtime/3.6/lib/python3.6/site-packages/flask/app.py", line 1821, in handle_user_exception
    reraise(exc_type, exc_value, tb)
  File "/home/tracerstudy/virtualenv/realtime/3.6/lib/python3.6/site-packages/flask/_compat.py", line 39, in reraise
    raise value
  File "/home/tracerstudy/virtualenv/realtime/3.6/lib/python3.6/site-packages/flask/app.py", line 1950, in full_dispatch_request
    rv = self.dispatch_request()
  File "/home/tracerstudy/virtualenv/realtime/3.6/lib/python3.6/site-packages/flask/app.py", line 1936, in dispatch_request
    return self.view_functions[rule.endpoint](**req.view_args)
  File "/home/tracerstudy/realtime/main.py", line 178, in piechart_non
    os.remove(rmv)
FileNotFoundError: [Errno 2] No such file or directory: '../public_html/cdc/data_olah/9a121e4a82d9e16ba1a6e15a2f20dc91.png'
Exception on /piechart_non/15 [GET]
Traceback (most recent call last):
  File "/home/tracerstudy/virtualenv/realtime/3.6/lib/python3.6/site-packages/flask/app.py", line 2447, in wsgi_app
    response = self.full_dispatch_request()
  File "/home/tracerstudy/virtualenv/realtime/3.6/lib/python3.6/site-packages/flask/app.py", line 1952, in full_dispatch_request
    rv = self.handle_user_exception(e)
  File "/home/tracerstudy/virtualenv/realtime/3.6/lib/python3.6/site-packages/flask/app.py", line 1821, in handle_user_exception
    reraise(exc_type, exc_value, tb)
  File "/home/tracerstudy/virtualenv/realtime/3.6/lib/python3.6/site-packages/flask/_compat.py", line 39, in reraise
    raise value
  File "/home/tracerstudy/virtualenv/realtime/3.6/lib/python3.6/site-packages/flask/app.py", line 1950, in full_dispatch_request
    rv = self.dispatch_request()
  File "/home/tracerstudy/virtualenv/realtime/3.6/lib/python3.6/site-packages/flask/app.py", line 1936, in dispatch_request
    return self.view_functions[rule.endpoint](**req.view_args)
  File "/home/tracerstudy/realtime/main.py", line 146, in piechart_non
    df_olah = df.dropna(subset=[fitur[1]], axis=0)
  File "/home/tracerstudy/virtualenv/realtime/3.6/lib/python3.6/site-packages/pandas/core/frame.py", line 5004, in dropna
    raise KeyError(list(np.compress(check, subset)))
KeyError: ['DR-1 Darimana anda mendapatkan informasi tracer studi ini pertama kali?* (pilih salah satu)']
Exception on /prodi_piechart/19 [POST]
Traceback (most recent call last):
  File "/home/tracerstudy/virtualenv/realtime/3.6/lib/python3.6/site-packages/flask/app.py", line 2447, in wsgi_app
    response = self.full_dispatch_request()
  File "/home/tracerstudy/virtualenv/realtime/3.6/lib/python3.6/site-packages/flask/app.py", line 1952, in full_dispatch_request
    rv = self.handle_user_exception(e)
  File "/home/tracerstudy/virtualenv/realtime/3.6/lib/python3.6/site-packages/flask/app.py", line 1821, in handle_user_exception
    reraise(exc_type, exc_value, tb)
  File "/home/tracerstudy/virtualenv/realtime/3.6/lib/python3.6/site-packages/flask/_compat.py", line 39, in reraise
    raise value
  File "/home/tracerstudy/virtualenv/realtime/3.6/lib/python3.6/site-packages/flask/app.py", line 1950, in full_dispatch_request
    rv = self.dispatch_request()
  File "/home/tracerstudy/virtualenv/realtime/3.6/lib/python3.6/site-packages/flask/app.py", line 1936, in dispatch_request
    return self.view_functions[rule.endpoint](**req.view_args)
  File "/home/tracerstudy/realtime/main.py", line 252, in prodi_piechart
    plt.pie(x=df_olah['NRP'], labels=atribut, autopct=make_autopct(df_olah['NRP']), labeldistance=1.2, explode=explode)
  File "/home/tracerstudy/virtualenv/realtime/3.6/lib/python3.6/site-packages/matplotlib/pyplot.py", line 2834, in pie
    **({"data": data} if data is not None else {}))
  File "/home/tracerstudy/virtualenv/realtime/3.6/lib/python3.6/site-packages/matplotlib/__init__.py", line 1438, in inner
    return func(ax, *map(sanitize_sequence, args), **kwargs)
  File "/home/tracerstudy/virtualenv/realtime/3.6/lib/python3.6/site-packages/matplotlib/axes/_axes.py", line 3024, in pie
    raise ValueError("'label' must be of length 'x'")
ValueError: 'label' must be of length 'x'
Exception on /piechart/21 [GET]
Traceback (most recent call last):
  File "/home/tracerstudy/virtualenv/realtime/3.6/lib/python3.6/site-packages/flask/app.py", line 2447, in wsgi_app
    response = self.full_dispatch_request()
  File "/home/tracerstudy/virtualenv/realtime/3.6/lib/python3.6/site-packages/flask/app.py", line 1952, in full_dispatch_request
    rv = self.handle_user_exception(e)
  File "/home/tracerstudy/virtualenv/realtime/3.6/lib/python3.6/site-packages/flask/app.py", line 1821, in handle_user_exception
    reraise(exc_type, exc_value, tb)
  File "/home/tracerstudy/virtualenv/realtime/3.6/lib/python3.6/site-packages/flask/_compat.py", line 39, in reraise
    raise value
  File "/home/tracerstudy/virtualenv/realtime/3.6/lib/python3.6/site-packages/flask/app.py", line 1950, in full_dispatch_request
    rv = self.dispatch_request()
  File "/home/tracerstudy/virtualenv/realtime/3.6/lib/python3.6/site-packages/flask/app.py", line 1936, in dispatch_request
    return self.view_functions[rule.endpoint](**req.view_args)
  File "/home/tracerstudy/realtime/main.py", line 81, in piechart
    cek = array_diff(index,df_olah[fitur[1]].values)
  File "/home/tracerstudy/realtime/main.py", line 355, in array_diff
    return [x for x in a if x not in b]
TypeError: 'function' object is not iterable
Exception on /piechart/21 [GET]
Traceback (most recent call last):
  File "/home/tracerstudy/virtualenv/realtime/3.6/lib/python3.6/site-packages/flask/app.py", line 2447, in wsgi_app
    response = self.full_dispatch_request()
  File "/home/tracerstudy/virtualenv/realtime/3.6/lib/python3.6/site-packages/flask/app.py", line 1952, in full_dispatch_request
    rv = self.handle_user_exception(e)
  File "/home/tracerstudy/virtualenv/realtime/3.6/lib/python3.6/site-packages/flask/app.py", line 1821, in handle_user_exception
    reraise(exc_type, exc_value, tb)
  File "/home/tracerstudy/virtualenv/realtime/3.6/lib/python3.6/site-packages/flask/_compat.py", line 39, in reraise
    raise value
  File "/home/tracerstudy/virtualenv/realtime/3.6/lib/python3.6/site-packages/flask/app.py", line 1950, in full_dispatch_request
    rv = self.dispatch_request()
  File "/home/tracerstudy/virtualenv/realtime/3.6/lib/python3.6/site-packages/flask/app.py", line 1936, in dispatch_request
    return self.view_functions[rule.endpoint](**req.view_args)
  File "/home/tracerstudy/realtime/main.py", line 81, in piechart
    cek = array_diff(index,df_olah[fitur[1]].values)
  File "/home/tracerstudy/realtime/main.py", line 355, in array_diff
    return [x for x in a if x not in b]
TypeError: 'function' object is not iterable
Exception on /piechart/21 [GET]
Traceback (most recent call last):
  File "/home/tracerstudy/virtualenv/realtime/3.6/lib/python3.6/site-packages/flask/app.py", line 2447, in wsgi_app
    response = self.full_dispatch_request()
  File "/home/tracerstudy/virtualenv/realtime/3.6/lib/python3.6/site-packages/flask/app.py", line 1952, in full_dispatch_request
    rv = self.handle_user_exception(e)
  File "/home/tracerstudy/virtualenv/realtime/3.6/lib/python3.6/site-packages/flask/app.py", line 1821, in handle_user_exception
    reraise(exc_type, exc_value, tb)
  File "/home/tracerstudy/virtualenv/realtime/3.6/lib/python3.6/site-packages/flask/_compat.py", line 39, in reraise
    raise value
  File "/home/tracerstudy/virtualenv/realtime/3.6/lib/python3.6/site-packages/flask/app.py", line 1950, in full_dispatch_request
    rv = self.dispatch_request()
  File "/home/tracerstudy/virtualenv/realtime/3.6/lib/python3.6/site-packages/flask/app.py", line 1936, in dispatch_request
    return self.view_functions[rule.endpoint](**req.view_args)
  File "/home/tracerstudy/realtime/main.py", line 81, in piechart
    cek = array_diff(index,df_olah[fitur[1]].values)
  File "/home/tracerstudy/realtime/main.py", line 355, in array_diff
    return [x for x in a if x not in b]
TypeError: 'function' object is not iterable
Exception on /piechart/21 [GET]
Traceback (most recent call last):
  File "/home/tracerstudy/virtualenv/realtime/3.6/lib/python3.6/site-packages/flask/app.py", line 2447, in wsgi_app
    response = self.full_dispatch_request()
  File "/home/tracerstudy/virtualenv/realtime/3.6/lib/python3.6/site-packages/flask/app.py", line 1952, in full_dispatch_request
    rv = self.handle_user_exception(e)
  File "/home/tracerstudy/virtualenv/realtime/3.6/lib/python3.6/site-packages/flask/app.py", line 1821, in handle_user_exception
    reraise(exc_type, exc_value, tb)
  File "/home/tracerstudy/virtualenv/realtime/3.6/lib/python3.6/site-packages/flask/_compat.py", line 39, in reraise
    raise value
  File "/home/tracerstudy/virtualenv/realtime/3.6/lib/python3.6/site-packages/flask/app.py", line 1950, in full_dispatch_request
    rv = self.dispatch_request()
  File "/home/tracerstudy/virtualenv/realtime/3.6/lib/python3.6/site-packages/flask/app.py", line 1936, in dispatch_request
    return self.view_functions[rule.endpoint](**req.view_args)
  File "/home/tracerstudy/realtime/main.py", line 81, in piechart
    cek = array_diff(index,df_olah[fitur[1]].values)
  File "/home/tracerstudy/realtime/main.py", line 355, in array_diff
    return [x for x in a if x not in b]
TypeError: 'function' object is not iterable
Exception on /piechart/21 [GET]
Traceback (most recent call last):
  File "/home/tracerstudy/virtualenv/realtime/3.6/lib/python3.6/site-packages/flask/app.py", line 2447, in wsgi_app
    response = self.full_dispatch_request()
  File "/home/tracerstudy/virtualenv/realtime/3.6/lib/python3.6/site-packages/flask/app.py", line 1952, in full_dispatch_request
    rv = self.handle_user_exception(e)
  File "/home/tracerstudy/virtualenv/realtime/3.6/lib/python3.6/site-packages/flask/app.py", line 1821, in handle_user_exception
    reraise(exc_type, exc_value, tb)
  File "/home/tracerstudy/virtualenv/realtime/3.6/lib/python3.6/site-packages/flask/_compat.py", line 39, in reraise
    raise value
  File "/home/tracerstudy/virtualenv/realtime/3.6/lib/python3.6/site-packages/flask/app.py", line 1950, in full_dispatch_request
    rv = self.dispatch_request()
  File "/home/tracerstudy/virtualenv/realtime/3.6/lib/python3.6/site-packages/flask/app.py", line 1936, in dispatch_request
    return self.view_functions[rule.endpoint](**req.view_args)
  File "/home/tracerstudy/realtime/main.py", line 81, in piechart
    cek = array_diff(index,df_olah[fitur[1]].values)
  File "/home/tracerstudy/realtime/main.py", line 355, in array_diff
    return [x for x in a if x not in b]
TypeError: 'function' object is not iterable
Exception on /piechart/21 [GET]
Traceback (most recent call last):
  File "/home/tracerstudy/virtualenv/realtime/3.6/lib/python3.6/site-packages/flask/app.py", line 2447, in wsgi_app
    response = self.full_dispatch_request()
  File "/home/tracerstudy/virtualenv/realtime/3.6/lib/python3.6/site-packages/flask/app.py", line 1952, in full_dispatch_request
    rv = self.handle_user_exception(e)
  File "/home/tracerstudy/virtualenv/realtime/3.6/lib/python3.6/site-packages/flask/app.py", line 1821, in handle_user_exception
    reraise(exc_type, exc_value, tb)
  File "/home/tracerstudy/virtualenv/realtime/3.6/lib/python3.6/site-packages/flask/_compat.py", line 39, in reraise
    raise value
  File "/home/tracerstudy/virtualenv/realtime/3.6/lib/python3.6/site-packages/flask/app.py", line 1950, in full_dispatch_request
    rv = self.dispatch_request()
  File "/home/tracerstudy/virtualenv/realtime/3.6/lib/python3.6/site-packages/flask/app.py", line 1936, in dispatch_request
    return self.view_functions[rule.endpoint](**req.view_args)
  File "/home/tracerstudy/realtime/main.py", line 81, in piechart
    cek = array_diff(index,df_olah[fitur[1]].values)
  File "/home/tracerstudy/realtime/main.py", line 355, in array_diff
    return [x for x in a if x not in b]
TypeError: 'function' object is not iterable
Exception on /piechart/21 [GET]
Traceback (most recent call last):
  File "/home/tracerstudy/virtualenv/realtime/3.6/lib/python3.6/site-packages/flask/app.py", line 2447, in wsgi_app
    response = self.full_dispatch_request()
  File "/home/tracerstudy/virtualenv/realtime/3.6/lib/python3.6/site-packages/flask/app.py", line 1952, in full_dispatch_request
    rv = self.handle_user_exception(e)
  File "/home/tracerstudy/virtualenv/realtime/3.6/lib/python3.6/site-packages/flask/app.py", line 1821, in handle_user_exception
    reraise(exc_type, exc_value, tb)
  File "/home/tracerstudy/virtualenv/realtime/3.6/lib/python3.6/site-packages/flask/_compat.py", line 39, in reraise
    raise value
  File "/home/tracerstudy/virtualenv/realtime/3.6/lib/python3.6/site-packages/flask/app.py", line 1950, in full_dispatch_request
    rv = self.dispatch_request()
  File "/home/tracerstudy/virtualenv/realtime/3.6/lib/python3.6/site-packages/flask/app.py", line 1936, in dispatch_request
    return self.view_functions[rule.endpoint](**req.view_args)
  File "/home/tracerstudy/realtime/main.py", line 81, in piechart
    cek = array_diff(index,df_olah[fitur[1]].values)
  File "/home/tracerstudy/realtime/main.py", line 355, in array_diff
    return [x for x in a if x not in b]
TypeError: 'function' object is not iterable
Exception on /piechart/21 [GET]
Traceback (most recent call last):
  File "/home/tracerstudy/virtualenv/realtime/3.6/lib/python3.6/site-packages/flask/app.py", line 2447, in wsgi_app
    response = self.full_dispatch_request()
  File "/home/tracerstudy/virtualenv/realtime/3.6/lib/python3.6/site-packages/flask/app.py", line 1952, in full_dispatch_request
    rv = self.handle_user_exception(e)
  File "/home/tracerstudy/virtualenv/realtime/3.6/lib/python3.6/site-packages/flask/app.py", line 1821, in handle_user_exception
    reraise(exc_type, exc_value, tb)
  File "/home/tracerstudy/virtualenv/realtime/3.6/lib/python3.6/site-packages/flask/_compat.py", line 39, in reraise
    raise value
  File "/home/tracerstudy/virtualenv/realtime/3.6/lib/python3.6/site-packages/flask/app.py", line 1950, in full_dispatch_request
    rv = self.dispatch_request()
  File "/home/tracerstudy/virtualenv/realtime/3.6/lib/python3.6/site-packages/flask/app.py", line 1936, in dispatch_request
    return self.view_functions[rule.endpoint](**req.view_args)
  File "/home/tracerstudy/realtime/main.py", line 81, in piechart
    cek = array_diff(index,df_olah[fitur[1]].values)
  File "/home/tracerstudy/realtime/main.py", line 355, in array_diff
    return [x for x in a if x not in b]
TypeError: 'function' object is not iterable
Exception on /piechart/21 [GET]
Traceback (most recent call last):
  File "/home/tracerstudy/virtualenv/realtime/3.6/lib/python3.6/site-packages/flask/app.py", line 2447, in wsgi_app
    response = self.full_dispatch_request()
  File "/home/tracerstudy/virtualenv/realtime/3.6/lib/python3.6/site-packages/flask/app.py", line 1952, in full_dispatch_request
    rv = self.handle_user_exception(e)
  File "/home/tracerstudy/virtualenv/realtime/3.6/lib/python3.6/site-packages/flask/app.py", line 1821, in handle_user_exception
    reraise(exc_type, exc_value, tb)
  File "/home/tracerstudy/virtualenv/realtime/3.6/lib/python3.6/site-packages/flask/_compat.py", line 39, in reraise
    raise value
  File "/home/tracerstudy/virtualenv/realtime/3.6/lib/python3.6/site-packages/flask/app.py", line 1950, in full_dispatch_request
    rv = self.dispatch_request()
  File "/home/tracerstudy/virtualenv/realtime/3.6/lib/python3.6/site-packages/flask/app.py", line 1936, in dispatch_request
    return self.view_functions[rule.endpoint](**req.view_args)
  File "/home/tracerstudy/realtime/main.py", line 81, in piechart
    cek = array_diff(index,df_olah[fitur[1]].values)
  File "/home/tracerstudy/realtime/main.py", line 355, in array_diff
    return [x for x in a if x not in b]
TypeError: 'function' object is not iterable
Exception on /piechart/21 [GET]
Traceback (most recent call last):
  File "/home/tracerstudy/virtualenv/realtime/3.6/lib/python3.6/site-packages/flask/app.py", line 2447, in wsgi_app
    response = self.full_dispatch_request()
  File "/home/tracerstudy/virtualenv/realtime/3.6/lib/python3.6/site-packages/flask/app.py", line 1952, in full_dispatch_request
    rv = self.handle_user_exception(e)
  File "/home/tracerstudy/virtualenv/realtime/3.6/lib/python3.6/site-packages/flask/app.py", line 1821, in handle_user_exception
    reraise(exc_type, exc_value, tb)
  File "/home/tracerstudy/virtualenv/realtime/3.6/lib/python3.6/site-packages/flask/_compat.py", line 39, in reraise
    raise value
  File "/home/tracerstudy/virtualenv/realtime/3.6/lib/python3.6/site-packages/flask/app.py", line 1950, in full_dispatch_request
    rv = self.dispatch_request()
  File "/home/tracerstudy/virtualenv/realtime/3.6/lib/python3.6/site-packages/flask/app.py", line 1936, in dispatch_request
    return self.view_functions[rule.endpoint](**req.view_args)
  File "/home/tracerstudy/realtime/main.py", line 81, in piechart
    cek = array_diff(index,df_olah[fitur[1]].values)
  File "/home/tracerstudy/realtime/main.py", line 355, in array_diff
    return [x for x in a if x not in b]
TypeError: 'function' object is not iterable
